<?xml version="1.0"?>
<!-- Revolute-Revolute Manipulator -->
<robot name="ugv" xmlns:xacro="http://www.ros.org/wiki/xacro">

  <!-- Constants for robot dimensions -->
  <xacro:property name="PI" value="3.1415926535897931"/>
  <xacro:property name="mass" value="5" />
  <xacro:property name="length" value="0.813" />
  <xacro:property name="width" value="0.5045" />
  <xacro:property name="height" value="0.202" />
  <xacro:property name="cylinder_length" value="0.025" />
  <xacro:property name="cylinder_radius" value="0.055" />
  <xacro:property name="width_diff" value="0.05" />
  <xacro:property name="height_diff" value="0.05" />
  <xacro:property name="length_diff" value="0.05" />

  <!-- Import all Gazebo-customization elements, including Gazebo colors -->
  <xacro:include filename="$(find testing)/urdf/ugv.gazebo" />
  <!-- Import Rviz colors -->
  <xacro:include filename="$(find testing)/urdf/materials.xacro" />

  <!-- Used for fixing robot to Gazebo 'base_link' -->
  <link name="base_footprint"/>

  <joint name="footprint_joint" type="fixed">
    <axis xyz="0 0 0" />
    <origin xyz="0 0 ${height/2}" rpy="0 0 0"/>
    <parent link="base_footprint"/>
    <child link="chassis"/>
  </joint>


  <!-- Base Link -->
  <link name="chassis">
    <collision>
      <origin xyz="0 0 ${height/2.0}" rpy="0 0 0"/>
      <geometry>
	<box size="${width} ${width} ${height}"/>
      </geometry>
    </collision>

    <visual>
      <origin xyz="0 0 ${height/2.0}" rpy="0 0 0"/>
      <geometry>
        <mesh filename="package://testing/meshes/UGV.stl"/>
      </geometry>
    </visual>

    <inertial>
      <origin xyz="0 0 ${height/2.0}" rpy="0 0 0"/>
      <mass value="${mass}"/>
      <inertia
	  ixx="${mass / 12.0 * (width*width + height*height)}" ixy="0.0" ixz="0.0"
	  iyy="${mass / 12.0 * (height*height + width*width)}" iyz="0.0"
	  izz="${mass / 12.0 * (width*width + width*width)}"/>
    </inertial>
  </link>  

  <!-- LEFT WHEEL -->
  <joint name="left_wheel_joint" type="continuous">
    <parent link="chassis"/>
    <child link="left_wheel"/>
    <origin xyz="0.0 ${width/2 - cylinder_length - width_diff} ${height/2 - height_diff}" rpy="0 0 0"/>
    <axis xyz="0 1 0"/>
    <dynamics damping="0.7"/>
  </joint>


  <link name="left_wheel">
    <collision>
      <origin xyz="0 0 0" rpy="${PI/2.0} 0 0"/>
      <geometry>
  	<cylinder radius="${cylinder_radius}" length="${cylinder_length}"/>
      </geometry>
    </collision>

    <visual>
      <origin xyz="0 0 0" rpy="${PI/2.0} 0 0"/>
      <geometry>
  	<cylinder radius="${cylinder_radius}" length="${cylinder_length}"/>
      </geometry>
      <material name="black"/>
    </visual>

    <inertial>
      <origin xyz="0 0 0" rpy="${PI/2.0} 0 0"/>
      <mass value="0.5"/>
      <inertia
  	  ixx="0.0" ixy="0.0" ixz="0.0" iyy="0.0" iyz="0.0" izz="0.0"/>
    </inertial>
  </link>

  <!-- RIGHT WHEEL -->
  <joint name="right_wheel_joint" type="continuous">
    <parent link="chassis"/>
    <child link="right_wheel"/>
    <origin xyz="0.0 ${-width/2 + cylinder_length + width_diff} ${height/2 - height_diff}" rpy="0 0 0"/>
    <axis xyz="0 1 0"/>
    <dynamics damping="0.7"/>
  </joint>


  <link name="right_wheel">
    <collision>
      <origin xyz="0 0 0" rpy="${PI/2.0} 0 0"/>
      <geometry>
  	<cylinder radius="${cylinder_radius}" length="${cylinder_length}"/>
      </geometry>
    </collision>

    <visual>
      <origin xyz="0 0 0" rpy="${PI/2.0} 0 0"/>
      <geometry>
  	<cylinder radius="${cylinder_radius}" length="${cylinder_length}"/>
      </geometry>
    </visual>

    <inertial>
      <origin xyz="0 0 0" rpy="${PI/2.0} 0 0"/>
      <mass value="0.5"/>
      <inertia
  	  ixx="0.0" ixy="0.0" ixz="0.0" iyy="0.0" iyz="0.0" izz="0.0"/>
    </inertial>
  </link>

  <!-- LEFT WHEEL FRONT -->
  <joint name="left_wheel_front_joint" type="continuous">
    <parent link="chassis"/>
    <child link="left_wheel_front"/>
    <origin xyz="${length/2 - cylinder_radius - length_diff} ${width/2 - cylinder_length - width_diff} ${height/2 - height_diff}" rpy="0 0 0"/>
    <axis xyz="0 1 0"/>
    <dynamics damping="0.7"/>
  </joint>


  <link name="left_wheel_front">
    <collision>
      <origin xyz="0 0 0" rpy="${PI/2.0} 0 0"/>
      <geometry>
  	<cylinder radius="${cylinder_radius}" length="${cylinder_length}"/>
      </geometry>
    </collision>

    <visual>
      <origin xyz="0 0 0" rpy="${PI/2.0} 0 0"/>
      <geometry>
  	<cylinder radius="${cylinder_radius}" length="${cylinder_length}"/>
      </geometry>
    </visual>

    <inertial>
      <origin xyz="0 0 0" rpy="${PI/2.0} 0 0"/>
      <mass value="0.5"/>
      <inertia
  	  ixx="0.0" ixy="0.0" ixz="0.0" iyy="0.0" iyz="0.0" izz="0.0"/>
    </inertial>
  </link>

  <!-- RIGHT WHEEL FRONT -->
  <joint name="right_wheel_front_joint" type="continuous">
    <parent link="chassis"/>
    <child link="right_wheel_front"/>
    <origin xyz="${length/2 - cylinder_radius - length_diff} ${-width/2 + cylinder_length + width_diff} ${height/2 - height_diff}" rpy="0 0 0"/>
    <axis xyz="0 1 0"/>
    <dynamics damping="0.7"/>
  </joint>


  <link name="right_wheel_front">
    <collision>
      <origin xyz="0 0 0" rpy="${PI/2.0} 0 0"/>
      <geometry>
  	<cylinder radius="${cylinder_radius}" length="${cylinder_length}"/>
      </geometry>
    </collision>

    <visual>
      <origin xyz="0 0 0" rpy="${PI/2.0} 0 0"/>
      <geometry>
  	<cylinder radius="${cylinder_radius}" length="${cylinder_length}"/>
      </geometry>
    </visual>

    <inertial>
      <origin xyz="0 0 0" rpy="${PI/2.0} 0 0"/>
      <mass value="0.5"/>
      <inertia
  	  ixx="0.0" ixy="0.0" ixz="0.0" iyy="0.0" iyz="0.0" izz="0.0"/>
    </inertial>
  </link>

  <!-- LEFT WHEEL BACK -->
  <joint name="left_wheel_back_joint" type="continuous">
    <parent link="chassis"/>
    <child link="left_wheel_back"/>
    <origin xyz="${-length/2 + cylinder_radius} ${width/2 - cylinder_length - width_diff} ${height/2 - height_diff}" rpy="0 0 0"/>
    <axis xyz="0 1 0"/>
    <dynamics damping="0.7"/>
  </joint>


  <link name="left_wheel_back">
    <collision>
      <origin xyz="0 0 0" rpy="${PI/2.0} 0 0"/>
      <geometry>
  	<cylinder radius="${cylinder_radius}" length="${cylinder_length}"/>
      </geometry>
    </collision>

    <visual>
      <origin xyz="0 0 0" rpy="${PI/2.0} 0 0"/>
      <geometry>
  	<cylinder radius="${cylinder_radius}" length="${cylinder_length}"/>
      </geometry>
    </visual>

    <inertial>
      <origin xyz="0 0 0" rpy="${PI/2.0} 0 0"/>
      <mass value="0.5"/>
      <inertia
  	  ixx="0.0" ixy="0.0" ixz="0.0" iyy="0.0" iyz="0.0" izz="0.0"/>
    </inertial>
  </link>

  <!-- RIGHT WHEEL BACK -->
  <joint name="right_wheel_back_joint" type="continuous">
    <parent link="chassis"/>
    <child link="right_wheel_back"/>
    <origin xyz="${-length/2 + cylinder_radius} ${-width/2 + cylinder_length + width_diff} ${height/2 - height_diff}" rpy="0 0 0"/>
    <axis xyz="0 1 0"/>
    <dynamics damping="0.7"/>
  </joint>


  <link name="right_wheel_back">
    <collision>
      <origin xyz="0 0 0" rpy="${PI/2.0} 0 0"/>
      <geometry>
  	<cylinder radius="${cylinder_radius}" length="${cylinder_length}"/>
      </geometry>
    </collision>

    <visual>
      <origin xyz="0 0 0" rpy="${PI/2.0} 0 0"/>
      <geometry>
  	<cylinder radius="${cylinder_radius}" length="${cylinder_length}"/>
      </geometry>
    </visual>

    <inertial>
      <origin xyz="0 0 0" rpy="${PI/2.0} 0 0"/>
      <mass value="0.5"/>
      <inertia
  	  ixx="0.0" ixy="0.0" ixz="0.0" iyy="0.0" iyz="0.0" izz="0.0"/>
    </inertial>
  </link>


  
  <!-- HOKUYO LASER -->
  <joint name="hokuyo_joint" type="fixed">
    <axis xyz="0 0 0" />
    <origin xyz="0.3 0 ${height + 0.025}" rpy="0 0 0"/>
    <parent link="chassis"/>
    <child link="hokuyo_link"/>
  </joint>
  
  <!-- Hokuyo Laser -->
  <link name="hokuyo_link">
    <collision>
      <origin xyz="0 0 -0.025" rpy="0 0 0"/>
      <geometry>
	<box size="0.051 0.051 0.07"/>
      </geometry>
    </collision>

    <visual>
      <origin xyz="0 0 -0.05" rpy="0 0 0"/>
      <geometry>
        <mesh filename="package://testing/meshes/Hokuyo.stl"/>
      </geometry>
    </visual>

    <inertial>
      <mass value="1e-5" />
      <origin xyz="0 0 -0.05" rpy="0 0 0"/>
      <inertia ixx="1e-6" ixy="0" ixz="0" iyy="1e-6" iyz="0" izz="1e-6" />
    </inertial>
  </link>

  <!-- CAMERA -->
  <joint name="camera_joint" type="fixed">
    <axis xyz="0 0 0" />
    <origin xyz="0.3 0.1 ${height}" rpy="0 0 0"/>
    <parent link="chassis"/>
    <child link="camera_link"/>
  </joint>

  <!-- Camera -->
  <link name="camera_link">
    <collision>
      <origin xyz="0 0 0" rpy="0 0 0"/>
      <geometry>
  	<box size="0.05 0.05 0.05"/>
      </geometry>
    </collision>

    <visual>
      <origin xyz="0 0 0" rpy="0 0 0"/>
      <geometry>
  	<box size="0.05 0.05 0.05"/>
      </geometry>
    </visual>

    <inertial>
      <mass value="1e-5" />
      <origin xyz="0 0 0" rpy="0 0 0"/>
      <inertia ixx="1e-6" ixy="0" ixz="0" iyy="1e-6" iyz="0" izz="1e-6" />
    </inertial>
  </link>

  <!-- IMU -->
  <joint name="imu_joint" type="fixed">
    <axis xyz="0 0 0" />
    <origin xyz="0 0 ${height + 0.05}" rpy="0 0 0"/>
    <parent link="chassis"/>
    <child link="imu_link"/>
  </joint>

  <link name="imu_link">
    <collision>
      <origin xyz="0 0 0" rpy="0 0 0"/>
      <geometry>
  	<box size="0.05 0.05 0.05"/>
      </geometry>
    </collision>

    <visual>
      <origin xyz="0 0 0" rpy="0 0 0"/>
      <geometry>
  	<box size="0.05 0.05 0.05"/>
      </geometry>
    </visual>

    <inertial>
      <mass value="1e-5" />
      <origin xyz="0 0 0" rpy="0 0 0"/>
      <inertia ixx="1e-6" ixy="0" ixz="0" iyy="1e-6" iyz="0" izz="1e-6" />
    </inertial>
  </link>
  

  
  <!-- REFERENCES -->

  <gazebo reference="chassis">
    <visual>
      <material>  
	<ambient>0.19225 0.19225 0.19225 1.0</ambient>  
	<diffuse>0.50754 0.50754 0.50754 1.0</diffuse>  
	<specular>0.508273 0.508273 0.508273 1.0</specular>  
	<emissive>0.0 0.0 0.0 0.0</emissive>  
      </material>  
    </visual>
  </gazebo> 

  <gazebo reference="left_wheel">
    <material>Gazebo/GreyTransparent</material>
    <mu1 value="10000.0" />
    <mu2 value="10000.0" />
  </gazebo>

  <gazebo reference="right_wheel">
    <material>Gazebo/GreyTransparent</material>
    <mu1 value="10000.0" />
    <mu2 value="10000.0" />
  </gazebo>

  <gazebo reference="left_wheel_front">
    <material>Gazebo/GreyTransparent</material>
    <mu1 value="0.0" />
    <mu2 value="0.0" />
  </gazebo>

  <gazebo reference="right_wheel_front">
    <material>Gazebo/GreyTransparent</material>
    <mu1 value="0.0" />
    <mu2 value="0.0" />
  </gazebo>

  <gazebo reference="left_wheel_back">
    <material>Gazebo/GreyTransparent</material>
    <mu1 value="0.0" />
    <mu2 value="0.0" />
  </gazebo>
  
  <gazebo reference="right_wheel_back">
    <material>Gazebo/GreyTransparent</material>
    <mu1 value="0.0" />
    <mu2 value="0.0" />
  </gazebo>

  <gazebo reference="camera_link">
    <material>Gazebo/Red</material>
  </gazebo>

  
  

  <!-- generate an optical frame http://www.ros.org/reps/rep-0103.html#suffix-frames
      so that ros and opencv can operate on the camera frame correctly -->
  <joint name="camera_optical_joint" type="fixed"> 
    <!-- these values have to be these values otherwise the gazebo camera image
        won't be aligned properly with the frame it is supposedly originating from -->
    <origin xyz="0 0 0" rpy="${-pi/2} 0 ${-pi/2}"/>
    <parent link="camera_link"/>
    <child link="camera_link_optical"/>
  </joint>

  <link name="camera_link_optical">
  </link>

  <transmission name="left_tran">
    <type>transmission_interface/SimpleTransmission</type>
    <joint name="left_wheel_joint">
      <hardwareInterface>VelocityJointInterface</hardwareInterface>
    </joint>
    <actuator name="left_actuator">
      <mechanicalReduction>1</mechanicalReduction>
    </actuator>
  </transmission>

  <transmission name="right_tran">
    <type>transmission_interface/SimpleTransmission</type>
    <joint name="right_wheel_joint">
      <hardwareInterface>VelocityJointInterface</hardwareInterface>
    </joint>
    <actuator name="right_actuator">
      <mechanicalReduction>1</mechanicalReduction>
    </actuator>
  </transmission>

</robot>
