<?xml version="1.0"?>
<robot name="myfirst">

  <material name="blue">
    <color rgba="0 0 1 0.75"/>
  </material>
  <material name="black">
    <color rgba="0 0 0 1"/>
  </material>

  <link name="odom">
    <visual>
      <geometry>
	<cylinder length="0" radius="0"/>
      </geometry>
    </visual>
  </link>
  
  <link name="base_link">
    <visual>
      <geometry>
	<mesh filename="package://testing/meshes/UGV.stl"/>
      </geometry>
      <origin xyz="0 0 0" rpy="0 0 0"/>      
      <material name="blue"/>
    </visual>
  </link>

  <link name="hokuyo_link">
    <visual>
      <geometry>
	<mesh filename="package://testing/meshes/Hokuyo.stl"/>
      </geometry>
      <origin xyz="0 0 0" rpy="0 0 0"/>      
      <material name="black"/>
    </visual>
  </link>

  <link name="laser">
    <visual>
      <geometry>
	<cylinder length="0" radius="0"/>
      </geometry>
    </visual>
  </link>
  
  <!-- _________________JOINTS____________________ -->

  <joint name="world_to_body" type="planar">
    <origin xyz="0 0 0.101" rpy="0 0 0" />
    <parent link="odom"/>
    <child link="base_link"/>

    <axis xyz="0 0 1"/>
  </joint>

  <joint name="robot_to_laser" type="fixed">
    <origin xyz="0.3 0 0.1" rpy="0 0 0" />
    <parent link="base_link"/>
    <child link="hokuyo_link"/>
  </joint>

  <joint name="Hokuyo_to_laser" type="fixed">
    <origin xyz="0 0 0.05" rpy="0 0 0" />
    <parent link="hokuyo_link"/>
    <child link="laser"/>
  </joint>

  
</robot>
